2024-04-01 01:24:28,827 INFO    MainThread:13345 [wandb_setup.py:_flush():76] Current SDK version is 0.16.5
2024-04-01 01:24:28,827 INFO    MainThread:13345 [wandb_setup.py:_flush():76] Configure stats pid to 13345
2024-04-01 01:24:28,827 INFO    MainThread:13345 [wandb_setup.py:_flush():76] Loading settings from /home/navyansh/.config/wandb/settings
2024-04-01 01:24:28,827 INFO    MainThread:13345 [wandb_setup.py:_flush():76] Loading settings from /home/navyansh/Imp/galore-sam/wandb/settings
2024-04-01 01:24:28,827 INFO    MainThread:13345 [wandb_setup.py:_flush():76] Loading settings from environment variables: {}
2024-04-01 01:24:28,827 INFO    MainThread:13345 [wandb_setup.py:_flush():76] Applying setup settings: {'_disable_service': False}
2024-04-01 01:24:28,827 INFO    MainThread:13345 [wandb_setup.py:_flush():76] Inferring run settings from compute environment: {'program_relpath': 'train.py', 'program_abspath': '/home/navyansh/Imp/galore-sam/train.py', 'program': 'train.py'}
2024-04-01 01:24:28,827 INFO    MainThread:13345 [wandb_setup.py:_flush():76] Applying login settings: {}
2024-04-01 01:24:28,827 INFO    MainThread:13345 [wandb_init.py:_log_setup():527] Logging user logs to /home/navyansh/Imp/galore-sam/wandb/run-20240401_012428-5my1ql54/logs/debug.log
2024-04-01 01:24:28,827 INFO    MainThread:13345 [wandb_init.py:_log_setup():528] Logging internal logs to /home/navyansh/Imp/galore-sam/wandb/run-20240401_012428-5my1ql54/logs/debug-internal.log
2024-04-01 01:24:28,827 INFO    MainThread:13345 [wandb_init.py:init():567] calling init triggers
2024-04-01 01:24:28,828 INFO    MainThread:13345 [wandb_init.py:init():574] wandb.init called with sweep_config: {}
config: {}
2024-04-01 01:24:28,828 INFO    MainThread:13345 [wandb_init.py:init():617] starting backend
2024-04-01 01:24:28,828 INFO    MainThread:13345 [wandb_init.py:init():621] setting up manager
2024-04-01 01:24:28,830 INFO    MainThread:13345 [backend.py:_multiprocessing_setup():105] multiprocessing start_methods=fork,spawn,forkserver, using: spawn
2024-04-01 01:24:28,831 INFO    MainThread:13345 [wandb_init.py:init():629] backend started and connected
2024-04-01 01:24:28,834 INFO    MainThread:13345 [wandb_init.py:init():721] updated telemetry
2024-04-01 01:24:28,907 INFO    MainThread:13345 [wandb_init.py:init():754] communicating run to backend with 90.0 second timeout
2024-04-01 01:25:27,360 INFO    Thread-1  :13345 [retry.py:__call__():172] Retry attempt failed:
Traceback (most recent call last):
  File "/home/navyansh/Imp/SAMed/sam/lib/python3.8/site-packages/urllib3/connection.py", line 198, in _new_conn
    sock = connection.create_connection(
  File "/home/navyansh/Imp/SAMed/sam/lib/python3.8/site-packages/urllib3/util/connection.py", line 85, in create_connection
    raise err
  File "/home/navyansh/Imp/SAMed/sam/lib/python3.8/site-packages/urllib3/util/connection.py", line 73, in create_connection
    sock.connect(sa)
socket.timeout: timed out

The above exception was the direct cause of the following exception:

Traceback (most recent call last):
  File "/home/navyansh/Imp/SAMed/sam/lib/python3.8/site-packages/urllib3/connectionpool.py", line 793, in urlopen
    response = self._make_request(
  File "/home/navyansh/Imp/SAMed/sam/lib/python3.8/site-packages/urllib3/connectionpool.py", line 491, in _make_request
    raise new_e
  File "/home/navyansh/Imp/SAMed/sam/lib/python3.8/site-packages/urllib3/connectionpool.py", line 467, in _make_request
    self._validate_conn(conn)
  File "/home/navyansh/Imp/SAMed/sam/lib/python3.8/site-packages/urllib3/connectionpool.py", line 1099, in _validate_conn
    conn.connect()
  File "/home/navyansh/Imp/SAMed/sam/lib/python3.8/site-packages/urllib3/connection.py", line 616, in connect
    self.sock = sock = self._new_conn()
  File "/home/navyansh/Imp/SAMed/sam/lib/python3.8/site-packages/urllib3/connection.py", line 207, in _new_conn
    raise ConnectTimeoutError(
urllib3.exceptions.ConnectTimeoutError: (<urllib3.connection.HTTPSConnection object at 0x7f94c8915970>, 'Connection to api.wandb.ai timed out. (connect timeout=20)')

The above exception was the direct cause of the following exception:

Traceback (most recent call last):
  File "/home/navyansh/Imp/SAMed/sam/lib/python3.8/site-packages/requests/adapters.py", line 486, in send
    resp = conn.urlopen(
  File "/home/navyansh/Imp/SAMed/sam/lib/python3.8/site-packages/urllib3/connectionpool.py", line 847, in urlopen
    retries = retries.increment(
  File "/home/navyansh/Imp/SAMed/sam/lib/python3.8/site-packages/urllib3/util/retry.py", line 515, in increment
    raise MaxRetryError(_pool, url, reason) from reason  # type: ignore[arg-type]
urllib3.exceptions.MaxRetryError: HTTPSConnectionPool(host='api.wandb.ai', port=443): Max retries exceeded with url: /graphql (Caused by ConnectTimeoutError(<urllib3.connection.HTTPSConnection object at 0x7f94c8915970>, 'Connection to api.wandb.ai timed out. (connect timeout=20)'))

During handling of the above exception, another exception occurred:

Traceback (most recent call last):
  File "/home/navyansh/Imp/SAMed/sam/lib/python3.8/site-packages/wandb/sdk/lib/retry.py", line 131, in __call__
    result = self._call_fn(*args, **kwargs)
  File "/home/navyansh/Imp/SAMed/sam/lib/python3.8/site-packages/wandb/sdk/internal/internal_api.py", line 369, in execute
    return self.client.execute(*args, **kwargs)  # type: ignore
  File "/home/navyansh/Imp/SAMed/sam/lib/python3.8/site-packages/wandb/vendor/gql-0.2.0/wandb_gql/client.py", line 52, in execute
    result = self._get_result(document, *args, **kwargs)
  File "/home/navyansh/Imp/SAMed/sam/lib/python3.8/site-packages/wandb/vendor/gql-0.2.0/wandb_gql/client.py", line 60, in _get_result
    return self.transport.execute(document, *args, **kwargs)
  File "/home/navyansh/Imp/SAMed/sam/lib/python3.8/site-packages/wandb/sdk/lib/gql_request.py", line 58, in execute
    request = self.session.post(self.url, **post_args)
  File "/home/navyansh/Imp/SAMed/sam/lib/python3.8/site-packages/requests/sessions.py", line 637, in post
    return self.request("POST", url, data=data, json=json, **kwargs)
  File "/home/navyansh/Imp/SAMed/sam/lib/python3.8/site-packages/requests/sessions.py", line 589, in request
    resp = self.send(prep, **send_kwargs)
  File "/home/navyansh/Imp/SAMed/sam/lib/python3.8/site-packages/requests/sessions.py", line 703, in send
    r = adapter.send(request, **kwargs)
  File "/home/navyansh/Imp/SAMed/sam/lib/python3.8/site-packages/requests/adapters.py", line 507, in send
    raise ConnectTimeout(e, request=request)
requests.exceptions.ConnectTimeout: HTTPSConnectionPool(host='api.wandb.ai', port=443): Max retries exceeded with url: /graphql (Caused by ConnectTimeoutError(<urllib3.connection.HTTPSConnection object at 0x7f94c8915970>, 'Connection to api.wandb.ai timed out. (connect timeout=20)'))
2024-04-01 01:25:58,932 ERROR   MainThread:13345 [wandb_init.py:init():780] encountered error: Run initialization has timed out after 90.0 sec. 
Please refer to the documentation for additional information: https://docs.wandb.ai/guides/track/tracking-faq#initstarterror-error-communicating-with-wandb-process-
2024-04-01 01:26:00,951 ERROR   MainThread:13345 [wandb_init.py:init():1205] Run initialization has timed out after 90.0 sec. 
Please refer to the documentation for additional information: https://docs.wandb.ai/guides/track/tracking-faq#initstarterror-error-communicating-with-wandb-process-
Traceback (most recent call last):
  File "/home/navyansh/Imp/SAMed/sam/lib/python3.8/site-packages/wandb/sdk/wandb_init.py", line 1187, in init
    run = wi.init()
  File "/home/navyansh/Imp/SAMed/sam/lib/python3.8/site-packages/wandb/sdk/wandb_init.py", line 786, in init
    raise error
wandb.errors.CommError: Run initialization has timed out after 90.0 sec. 
Please refer to the documentation for additional information: https://docs.wandb.ai/guides/track/tracking-faq#initstarterror-error-communicating-with-wandb-process-
2024-04-01 01:26:03,937 WARNING MsgRouterThr:13345 [router.py:message_loop():77] message_loop has been closed
