2024-04-01 01:24:28,833 INFO    StreamThr :13585 [internal.py:wandb_internal():86] W&B internal server running at pid: 13585, started at: 2024-04-01 01:24:28.832514
2024-04-01 01:24:28,837 DEBUG   HandlerThread:13585 [handler.py:handle_request():146] handle_request: status
2024-04-01 01:24:28,839 INFO    WriterThread:13585 [datastore.py:open_for_write():87] open: /home/navyansh/Imp/galore-sam/wandb/run-20240401_012428-5my1ql54/run-5my1ql54.wandb
2024-04-01 01:24:28,841 DEBUG   SenderThread:13585 [sender.py:send():379] send: header
2024-04-01 01:24:28,910 DEBUG   SenderThread:13585 [sender.py:send():379] send: run
2024-04-01 01:24:33,910 DEBUG   HandlerThread:13585 [handler.py:handle_request():146] handle_request: keepalive
2024-04-01 01:24:38,911 DEBUG   HandlerThread:13585 [handler.py:handle_request():146] handle_request: keepalive
2024-04-01 01:24:43,913 DEBUG   HandlerThread:13585 [handler.py:handle_request():146] handle_request: keepalive
2024-04-01 01:24:48,914 DEBUG   HandlerThread:13585 [handler.py:handle_request():146] handle_request: keepalive
2024-04-01 01:24:53,915 DEBUG   HandlerThread:13585 [handler.py:handle_request():146] handle_request: keepalive
2024-04-01 01:24:58,916 DEBUG   HandlerThread:13585 [handler.py:handle_request():146] handle_request: keepalive
2024-04-01 01:25:03,918 DEBUG   HandlerThread:13585 [handler.py:handle_request():146] handle_request: keepalive
2024-04-01 01:25:08,919 DEBUG   HandlerThread:13585 [handler.py:handle_request():146] handle_request: keepalive
2024-04-01 01:25:13,920 DEBUG   HandlerThread:13585 [handler.py:handle_request():146] handle_request: keepalive
2024-04-01 01:25:18,921 DEBUG   HandlerThread:13585 [handler.py:handle_request():146] handle_request: keepalive
2024-04-01 01:25:23,922 DEBUG   HandlerThread:13585 [handler.py:handle_request():146] handle_request: keepalive
2024-04-01 01:25:28,924 DEBUG   HandlerThread:13585 [handler.py:handle_request():146] handle_request: keepalive
2024-04-01 01:25:32,287 INFO    SenderThread:13585 [retry.py:__call__():172] Retry attempt failed:
Traceback (most recent call last):
  File "/home/navyansh/Imp/SAMed/sam/lib/python3.8/site-packages/urllib3/connection.py", line 198, in _new_conn
    sock = connection.create_connection(
  File "/home/navyansh/Imp/SAMed/sam/lib/python3.8/site-packages/urllib3/util/connection.py", line 85, in create_connection
    raise err
  File "/home/navyansh/Imp/SAMed/sam/lib/python3.8/site-packages/urllib3/util/connection.py", line 73, in create_connection
    sock.connect(sa)
socket.timeout: timed out

The above exception was the direct cause of the following exception:

Traceback (most recent call last):
  File "/home/navyansh/Imp/SAMed/sam/lib/python3.8/site-packages/urllib3/connectionpool.py", line 793, in urlopen
    response = self._make_request(
  File "/home/navyansh/Imp/SAMed/sam/lib/python3.8/site-packages/urllib3/connectionpool.py", line 491, in _make_request
    raise new_e
  File "/home/navyansh/Imp/SAMed/sam/lib/python3.8/site-packages/urllib3/connectionpool.py", line 467, in _make_request
    self._validate_conn(conn)
  File "/home/navyansh/Imp/SAMed/sam/lib/python3.8/site-packages/urllib3/connectionpool.py", line 1099, in _validate_conn
    conn.connect()
  File "/home/navyansh/Imp/SAMed/sam/lib/python3.8/site-packages/urllib3/connection.py", line 616, in connect
    self.sock = sock = self._new_conn()
  File "/home/navyansh/Imp/SAMed/sam/lib/python3.8/site-packages/urllib3/connection.py", line 207, in _new_conn
    raise ConnectTimeoutError(
urllib3.exceptions.ConnectTimeoutError: (<urllib3.connection.HTTPSConnection object at 0x7f6920531c70>, 'Connection to api.wandb.ai timed out. (connect timeout=20)')

The above exception was the direct cause of the following exception:

Traceback (most recent call last):
  File "/home/navyansh/Imp/SAMed/sam/lib/python3.8/site-packages/requests/adapters.py", line 486, in send
    resp = conn.urlopen(
  File "/home/navyansh/Imp/SAMed/sam/lib/python3.8/site-packages/urllib3/connectionpool.py", line 847, in urlopen
    retries = retries.increment(
  File "/home/navyansh/Imp/SAMed/sam/lib/python3.8/site-packages/urllib3/util/retry.py", line 515, in increment
    raise MaxRetryError(_pool, url, reason) from reason  # type: ignore[arg-type]
urllib3.exceptions.MaxRetryError: HTTPSConnectionPool(host='api.wandb.ai', port=443): Max retries exceeded with url: /graphql (Caused by ConnectTimeoutError(<urllib3.connection.HTTPSConnection object at 0x7f6920531c70>, 'Connection to api.wandb.ai timed out. (connect timeout=20)'))

During handling of the above exception, another exception occurred:

Traceback (most recent call last):
  File "/home/navyansh/Imp/SAMed/sam/lib/python3.8/site-packages/wandb/sdk/lib/retry.py", line 131, in __call__
    result = self._call_fn(*args, **kwargs)
  File "/home/navyansh/Imp/SAMed/sam/lib/python3.8/site-packages/wandb/sdk/internal/internal_api.py", line 369, in execute
    return self.client.execute(*args, **kwargs)  # type: ignore
  File "/home/navyansh/Imp/SAMed/sam/lib/python3.8/site-packages/wandb/vendor/gql-0.2.0/wandb_gql/client.py", line 52, in execute
    result = self._get_result(document, *args, **kwargs)
  File "/home/navyansh/Imp/SAMed/sam/lib/python3.8/site-packages/wandb/vendor/gql-0.2.0/wandb_gql/client.py", line 60, in _get_result
    return self.transport.execute(document, *args, **kwargs)
  File "/home/navyansh/Imp/SAMed/sam/lib/python3.8/site-packages/wandb/sdk/lib/gql_request.py", line 58, in execute
    request = self.session.post(self.url, **post_args)
  File "/home/navyansh/Imp/SAMed/sam/lib/python3.8/site-packages/requests/sessions.py", line 637, in post
    return self.request("POST", url, data=data, json=json, **kwargs)
  File "/home/navyansh/Imp/SAMed/sam/lib/python3.8/site-packages/requests/sessions.py", line 589, in request
    resp = self.send(prep, **send_kwargs)
  File "/home/navyansh/Imp/SAMed/sam/lib/python3.8/site-packages/requests/sessions.py", line 703, in send
    r = adapter.send(request, **kwargs)
  File "/home/navyansh/Imp/SAMed/sam/lib/python3.8/site-packages/requests/adapters.py", line 507, in send
    raise ConnectTimeout(e, request=request)
requests.exceptions.ConnectTimeout: HTTPSConnectionPool(host='api.wandb.ai', port=443): Max retries exceeded with url: /graphql (Caused by ConnectTimeoutError(<urllib3.connection.HTTPSConnection object at 0x7f6920531c70>, 'Connection to api.wandb.ai timed out. (connect timeout=20)'))
2024-04-01 01:25:33,925 DEBUG   HandlerThread:13585 [handler.py:handle_request():146] handle_request: keepalive
2024-04-01 01:25:38,926 DEBUG   HandlerThread:13585 [handler.py:handle_request():146] handle_request: keepalive
2024-04-01 01:25:43,928 DEBUG   HandlerThread:13585 [handler.py:handle_request():146] handle_request: keepalive
2024-04-01 01:25:48,929 DEBUG   HandlerThread:13585 [handler.py:handle_request():146] handle_request: keepalive
2024-04-01 01:25:53,930 DEBUG   HandlerThread:13585 [handler.py:handle_request():146] handle_request: keepalive
2024-04-01 01:25:58,933 DEBUG   HandlerThread:13585 [handler.py:handle_request():146] handle_request: cancel
2024-04-01 01:25:58,933 DEBUG   HandlerThread:13585 [handler.py:handle_request():146] handle_request: cancel
2024-04-01 01:25:58,933 DEBUG   SenderThread:13585 [sender.py:send():388] Record cancelled: run
2024-04-01 01:25:58,934 DEBUG   HandlerThread:13585 [handler.py:handle_request():146] handle_request: status_report
2024-04-01 01:26:00,953 DEBUG   HandlerThread:13585 [handler.py:handle_request():146] handle_request: shutdown
2024-04-01 01:26:00,953 INFO    HandlerThread:13585 [handler.py:finish():866] shutting down handler
2024-04-01 01:26:01,934 INFO    SenderThread:13585 [sender.py:finish():1546] shutting down sender
2024-04-01 01:26:01,935 INFO    WriterThread:13585 [datastore.py:close():296] close: /home/navyansh/Imp/galore-sam/wandb/run-20240401_012428-5my1ql54/run-5my1ql54.wandb
